<mujoco model="h1_5">
  <compiler angle="radian" meshdir="meshes" autolimits="true"/>
  <statistic meansize="0.112107" extent="1.95557" center="0.0256948 1.86841e-05 -0.178443"/>
  <asset>
    <mesh name="L_hand_base_link" file="L_hand_base_link.STL"/>
    <mesh name="link11_L" file="link11_L.STL"/>
    <mesh name="link12_L" file="link12_L.STL"/>
    <mesh name="link13_L" file="link13_L.STL"/>
    <mesh name="link14_L" file="link14_L.STL"/>
    <mesh name="link15_L" file="link15_L.STL"/>
    <mesh name="link16_L" file="link16_L.STL"/>
    <mesh name="link17_L" file="link17_L.STL"/>
    <mesh name="link18_L" file="link18_L.STL"/>
    <mesh name="link19_L" file="link19_L.STL"/>
    <mesh name="link20_L" file="link20_L.STL"/>
    <mesh name="link21_L" file="link21_L.STL"/>
    <mesh name="link22_L" file="link22_L.STL"/>
    <mesh name="R_hand_base_link" file="R_hand_base_link.STL"/>
    <mesh name="link11_R" file="link11_R.STL"/>
    <mesh name="link12_R" file="link12_R.STL"/>
    <mesh name="link13_R" file="link13_R.STL"/>
    <mesh name="link14_R" file="link14_R.STL"/>
    <mesh name="link15_R" file="link15_R.STL"/>
    <mesh name="link16_R" file="link16_R.STL"/>
    <mesh name="link17_R" file="link17_R.STL"/>
    <mesh name="link18_R" file="link18_R.STL"/>
    <mesh name="link19_R" file="link19_R.STL"/>
    <mesh name="link20_R" file="link20_R.STL"/>
    <mesh name="link21_R" file="link21_R.STL"/>
    <mesh name="link22_R" file="link22_R.STL"/>
  </asset>
  <worldbody>
    <body name="L_thumb_proximal_base" pos="0.1231 -0.01696 0.02045" quat="-2.59735e-06 0.707107 0 0.707107">
        <inertial pos="0.0048817 0.00038782 -0.00722" quat="0.445981 0.352284 0.495833 0.656617" mass="0.0018869" diaginertia="8.66031e-08 6.87331e-08 4.94199e-08"/>
        <joint name="L_thumb_proximal_yaw_joint" pos="0 0 0" axis="0 0 1" range="-0.1 1.3" actuatorfrcrange="-1 1"/>
        <geom type="mesh" contype="0" conaffinity="0" group="1" density="0" rgba="0.7 0.7 0.7 1" mesh="link11_L"/>
        <geom type="mesh" rgba="0.7 0.7 0.7 1" mesh="link11_L"/>
        <body name="L_thumb_proximal" pos="0.0099867 0.0098242 -0.0089" quat="0.704571 -0.704573 -0.0598169 0.0598167">
            <inertial pos="0.021936 -0.01279 -0.0080386" quat="0.25452 0.660687 -0.251949 0.659723" mass="0.0066101" diaginertia="2.78701e-06 2.44024e-06 8.6466e-07"/>
            <joint name="L_thumb_proximal_pitch_joint" pos="0 0 0" axis="0 0 -1" range="-0.1 0.6" actuatorfrcrange="-1 1"/>
            <geom type="mesh" contype="0" conaffinity="0" group="1" density="0" rgba="0.7 0.7 0.7 1" mesh="link12_L"/>
            <geom type="mesh" rgba="0.7 0.7 0.7 1" mesh="link12_L"/>
            <body name="L_thumb_intermediate" pos="0.04407 -0.034553 -0.0008">
                <inertial pos="0.0095531 0.0016282 -0.0072002" quat="0.30738 0.636732 -0.307526 0.636803" mass="0.0037844" diaginertia="4.6532e-07 4.48114e-07 2.45646e-07"/>
                <joint name="L_thumb_intermediate_joint" pos="0 0 0" axis="0 0 -1" range="0 0.8" actuatorfrcrange="-1 1"/>
                <geom type="mesh" contype="0" conaffinity="0" group="1" density="0" rgba="0.7 0.7 0.7 1" mesh="link13_L"/>
                <geom type="mesh" rgba="0.7 0.7 0.7 1" mesh="link13_L"/>
                <body name="L_thumb_distal" pos="0.020248 -0.010156 -0.0012">
                    <inertial pos="0.0092888 -0.004953 -0.0060033" quat="0.266264 0.65596 -0.262836 0.655544" mass="0.003344" diaginertia="2.0026e-07 1.95246e-07 8.1594e-08"/>
                    <joint name="L_thumb_distal_joint" pos="0 0 0" axis="0 0 -1" range="0 1.2" actuatorfrcrange="-1 1"/>
                    <geom type="mesh" contype="0" conaffinity="0" group="1" density="0" rgba="0.7 0.7 0.7 1" mesh="link14_L"/>
                    <geom type="mesh" rgba="0.7 0.7 0.7 1" mesh="link14_L"/>
                    <site name="l_thumb_site" pos="0.025 -0.01 0" size="0.005" rgba="1 0 0 1" />
                </body>
            </body>
        </body>
    </body>
    <body name="L_index_proximal" pos="0.19053 0.00028533 0.032268" quat="0.706999 -0.0123409 -0.0123409 0.706999">
        <inertial pos="0.0012971 -0.011934 -0.0059998" quat="0.489677 0.510115 -0.489692 0.510099" mass="0.0042405" diaginertia="6.9402e-07 6.62904e-07 2.10916e-07"/>
        <joint name="L_index_proximal_joint" pos="0 0 0" axis="0 0 -1" range="0 1.7" actuatorfrcrange="-1 1"/>
        <geom type="mesh" contype="0" conaffinity="0" group="1" density="0" rgba="0.7 0.7 0.7 1" mesh="link15_L"/>
        <geom type="mesh" rgba="0.7 0.7 0.7 1" mesh="link15_L"/>
        <body name="L_index_intermediate" pos="-0.0024229 -0.032041 -0.001">
            <inertial pos="0.0021753 -0.019567 -0.005" quat="0.528694 0.469555 -0.528694 0.469555" mass="0.0045682" diaginertia="7.8176e-07 7.72427e-07 8.47209e-08"/>
            <joint name="L_index_intermediate_joint" pos="0 0 0" axis="0 0 -1" range="0 1.7" actuatorfrcrange="-1 1"/>
            <geom type="mesh" contype="0" conaffinity="0" group="1" density="0" rgba="0.7 0.7 0.7 1" mesh="link16_L"/>
            <geom type="mesh" rgba="0.7 0.7 0.7 1" mesh="link16_L"/>
            <site name="l_index_site" pos="0 -0.045 0" size="0.005" rgba="1 0 0 1" />
        </body>
    </body>
    <body name="L_middle_proximal" pos="0.1911 0.00028533 0.01295" quat="0.707107 0 0 0.707107">
        <inertial pos="0.0012971 -0.011934 -0.0059999" quat="0.489677 0.510115 -0.489692 0.510099" mass="0.0042405" diaginertia="6.9402e-07 6.62904e-07 2.10916e-07"/>
        <joint name="L_middle_proximal_joint" pos="0 0 0" axis="0 0 -1" range="0 1.7" actuatorfrcrange="-1 1"/>
        <geom type="mesh" contype="0" conaffinity="0" group="1" density="0" rgba="0.7 0.7 0.7 1" mesh="link17_L"/>
        <geom type="mesh" rgba="0.7 0.7 0.7 1" mesh="link17_L"/>
        <body name="L_middle_intermediate" pos="-0.0024229 -0.032041 -0.001">
            <inertial pos="0.001921 -0.020796 -0.0049999" quat="0.531603 0.466115 -0.531728 0.466262" mass="0.0050397" diaginertia="9.8385e-07 9.73288e-07 9.14016e-08"/>
            <joint name="L_middle_intermediate_joint" pos="0 0 0" axis="0 0 -1" range="0 1.7" actuatorfrcrange="-1 1"/>
            <geom type="mesh" contype="0" conaffinity="0" group="1" density="0" rgba="0.7 0.7 0.7 1" mesh="link18_L"/>
            <geom type="mesh" rgba="0.7 0.7 0.7 1" mesh="link18_L"/>
            <site name="l_middle_site" pos="0 -0.05 0" size="0.005" rgba="1 0 0 1" />
        </body>
    </body>
    <body name="L_ring_proximal" pos="0.19091 0.00028533 -0.0062872" quat="0.706864 0.0185099 0.0185099 0.706864">
        <inertial pos="0.0012971 -0.011934 -0.0059999" quat="0.489677 0.510114 -0.489692 0.510099" mass="0.0042405" diaginertia="6.9402e-07 6.62904e-07 2.10916e-07"/>
        <joint name="L_ring_proximal_joint" pos="0 0 0" axis="0 0 -1" range="0 1.7" actuatorfrcrange="-1 1"/>
        <geom type="mesh" contype="0" conaffinity="0" group="1" density="0" rgba="0.7 0.7 0.7 1" mesh="link19_L"/>
        <geom type="mesh" rgba="0.7 0.7 0.7 1" mesh="link19_L"/>
        <body name="L_ring_intermediate" pos="-0.0024229 -0.032041 -0.001">
            <inertial pos="0.0021753 -0.019567 -0.005" quat="0.528694 0.469556 -0.528694 0.469556" mass="0.0045682" diaginertia="7.8176e-07 7.72437e-07 8.47208e-08"/>
            <joint name="L_ring_intermediate_joint" pos="0 0 0" axis="0 0 -1" range="0 1.7" actuatorfrcrange="-1 1"/>
            <geom type="mesh" contype="0" conaffinity="0" group="1" density="0" rgba="0.7 0.7 0.7 1" mesh="link20_L"/>
            <geom type="mesh" rgba="0.7 0.7 0.7 1" mesh="link20_L"/>
            <site name="l_ring_site" pos="0 -0.045 0" size="0.005" rgba="1 0 0 1" />
        </body>
    </body>
    <body name="L_pinky_proximal" pos="0.18971 0.00028533 -0.025488" quat="0.706138 0.0370072 0.0370072 0.706138">
        <inertial pos="0.0012971 -0.011934 -0.0059999" quat="0.489677 0.510114 -0.489692 0.510099" mass="0.0042405" diaginertia="6.9402e-07 6.62904e-07 2.10916e-07"/>
        <joint name="L_pinky_proximal_joint" pos="0 0 0" axis="0 0 -1" range="0 1.7" actuatorfrcrange="-1 1"/>
        <geom type="mesh" contype="0" conaffinity="0" group="1" density="0" rgba="0.7 0.7 0.7 1" mesh="link21_L"/>
        <geom type="mesh" rgba="0.7 0.7 0.7 1" mesh="link21_L"/>
        <body name="L_pinky_intermediate" pos="-0.0024229 -0.032041 -0.001">
            <inertial pos="0.0024788 -0.016208 -0.0050001" quat="0.526797 0.471683 -0.526793 0.471687" mass="0.0036036" diaginertia="4.4881e-07 4.43809e-07 6.5736e-08"/>
            <joint name="L_pinky_intermediate_joint" pos="0 0 0" axis="0 0 -1" range="0 1.7" actuatorfrcrange="-1 1"/>
            <geom type="mesh" contype="0" conaffinity="0" group="1" density="0" rgba="0.7 0.7 0.7 1" mesh="link22_L"/>
            <geom type="mesh" rgba="0.7 0.7 0.7 1" mesh="link22_L"/>
            <site name="l_pinky_site" pos="0 -0.04 0" size="0.005" rgba="1 0 0 1" />
        </body>
    </body>
    <body name="R_thumb_proximal_base" pos="0.1231 0.01696 0.02045" quat="-0.707107 -2.59735e-06 -0.707107 0">
        <inertial pos="-0.0048064 0.0009382 -0.00757" quat="0.515015 0.680854 0.408023 0.323596" mass="0.0018869" diaginertia="8.66026e-08 6.8732e-08 4.94194e-08"/>
        <joint name="R_thumb_proximal_yaw_joint" pos="0 0 0" axis="0 0 -1" range="-0.1 1.3" actuatorfrcrange="-1 1"/>
        <geom type="mesh" contype="0" conaffinity="0" group="1" density="0" rgba="0.7 0.7 0.7 1" mesh="link11_R"/>
        <geom type="mesh" rgba="0.7 0.7 0.7 1" mesh="link11_R"/>
        <body name="R_thumb_proximal" pos="-0.0088099 0.010892 -0.00925" quat="0.0996843 0.0996847 0.700046 0.700044">
            <inertial pos="0.021932 0.012785 -0.0080386" quat="-0.254474 0.660716 0.251893 0.659733" mass="0.0066075" diaginertia="2.78601e-06 2.43933e-06 8.64566e-07"/>
            <joint name="R_thumb_proximal_pitch_joint" pos="0 0 0" axis="0 0 1" range="-0.1 0.6" actuatorfrcrange="-1 1"/>
            <geom type="mesh" contype="0" conaffinity="0" group="1" density="0" rgba="0.7 0.7 0.7 1" mesh="link12_R"/>
            <geom type="mesh" rgba="0.7 0.7 0.7 1" mesh="link12_R"/>
            <body name="R_thumb_intermediate" pos="0.04407 0.034553 -0.0008">
            <inertial pos="0.0095544 -0.0016282 -0.0071997" quat="0.636718 0.307389 -0.636802 0.307548" mass="0.0037847" diaginertia="4.6531e-07 4.48089e-07 2.45661e-07"/>
            <joint name="R_thumb_intermediate_joint" pos="0 0 0" axis="0 0 1" range="0 0.8" actuatorfrcrange="-1 1"/>
            <geom type="mesh" contype="0" conaffinity="0" group="1" density="0" rgba="0.7 0.7 0.7 1" mesh="link13_R"/>
            <geom type="mesh" rgba="0.7 0.7 0.7 1" mesh="link13_R"/>
            <body name="R_thumb_distal" pos="0.020248 0.010156 -0.0012">
                <inertial pos="0.0092888 0.0049529 -0.0060033" quat="-0.266294 0.655967 0.262806 0.655537" mass="0.0033441" diaginertia="2.0026e-07 1.95247e-07 8.1593e-08"/>
                <joint name="R_thumb_distal_joint" pos="0 0 0" axis="0 0 1" range="0 1.2" actuatorfrcrange="-1 1"/>
                <geom type="mesh" contype="0" conaffinity="0" group="1" density="0" rgba="0.7 0.7 0.7 1" mesh="link14_R"/>
                <geom type="mesh" rgba="0.7 0.7 0.7 1" mesh="link14_R"/>
                <site name="r_thumb_site" pos="0.025 0.01 0" size="0.005" rgba="0 1 0 1" />
            </body>
            </body>
        </body>
    </body>
    <body name="R_index_proximal" pos="0.19053 -0.00028533 0.032268" quat="0.706999 0.0123358 -0.0123358 -0.706999">
        <inertial pos="0.0012259 0.011942 -0.0060001" quat="0.50867 0.49121 -0.508643 0.491172" mass="0.0042403" diaginertia="6.9398e-07 6.62871e-07 2.10909e-07"/>
        <joint name="R_index_proximal_joint" pos="0 0 0" axis="0 0 1" range="0 1.7" actuatorfrcrange="-1 1"/>
        <geom type="mesh" contype="0" conaffinity="0" group="1" density="0" rgba="0.7 0.7 0.7 1" mesh="link15_R"/>
        <geom type="mesh" rgba="0.7 0.7 0.7 1" mesh="link15_R"/>
        <body name="R_index_intermediate" pos="-0.0026138 0.032026 -0.001">
            <inertial pos="0.0019697 0.019589 -0.005" quat="0.466773 0.531152 -0.466773 0.531153" mass="0.0045683" diaginertia="7.8179e-07 7.72465e-07 8.47212e-08"/>
            <joint name="R_index_intermediate_joint" pos="0 0 0" axis="0 0 1" range="0 1.7" actuatorfrcrange="-1 1"/>
            <geom type="mesh" contype="0" conaffinity="0" group="1" density="0" rgba="0.7 0.7 0.7 1" mesh="link16_R"/>
            <geom type="mesh" rgba="0.7 0.7 0.7 1" mesh="link16_R"/>
            <site name="r_index_site" pos="0 0.045 0" size="0.005" rgba="0 1 0 1" />
        </body>
    </body>
    <body name="R_middle_proximal" pos="0.1911 -0.00028533 0.01295" quat="0.707107 -2.59735e-06 2.59735e-06 -0.707107">
        <inertial pos="0.001297 0.011934 -0.0060001" quat="0.510131 0.489693 -0.510105 0.489653" mass="0.0042403" diaginertia="6.9397e-07 6.62865e-07 2.10915e-07"/>
        <joint name="R_middle_proximal_joint" pos="0 0 0" axis="0 0 1" range="0 1.7" actuatorfrcrange="-1 1"/>
        <geom type="mesh" contype="0" conaffinity="0" group="1" density="0" rgba="0.7 0.7 0.7 1" mesh="link17_R"/>
        <geom type="mesh" rgba="0.7 0.7 0.7 1" mesh="link17_R"/>
        <body name="R_middle_intermediate" pos="-0.0024229 0.032041 -0.001">
            <inertial pos="0.001921 0.020796 -0.005" quat="0.466148 0.531627 -0.466229 0.531705" mass="0.0050396" diaginertia="9.8384e-07 9.73279e-07 9.14014e-08"/>
            <joint name="R_middle_intermediate_joint" pos="0 0 0" axis="0 0 1" range="0 1.7" actuatorfrcrange="-1 1"/>
            <geom type="mesh" contype="0" conaffinity="0" group="1" density="0" rgba="0.7 0.7 0.7 1" mesh="link18_R"/>
            <geom type="mesh" rgba="0.7 0.7 0.7 1" mesh="link18_R"/>
            <site name="r_middle_site" pos="0 0.05 0" size="0.005" rgba="0 1 0 1" />
        </body>
    </body>
    <body name="R_ring_proximal" pos="0.19091 -0.00028533 -0.0062872" quat="-0.706864 0.0185215 -0.0185215 0.706864">
        <inertial pos="0.001297 0.011934 -0.0060002" quat="0.510129 0.489691 -0.510107 0.489654" mass="0.0042403" diaginertia="6.9397e-07 6.62865e-07 2.10915e-07"/>
        <joint name="R_ring_proximal_joint" pos="0 0 0" axis="0 0 1" range="0 1.7" actuatorfrcrange="-1 1"/>
        <geom type="mesh" contype="0" conaffinity="0" group="1" density="0" rgba="0.7 0.7 0.7 1" mesh="link19_R"/>
        <geom type="mesh" rgba="0.7 0.7 0.7 1" mesh="link19_R"/>
        <body name="R_ring_intermediate" pos="-0.0024229 0.032041 -0.001">
            <inertial pos="0.0021753 0.019567 -0.005" quat="0.469554 0.528695 -0.469554 0.528695" mass="0.0045683" diaginertia="7.8177e-07 7.72448e-07 8.4722e-08"/>
            <joint name="R_ring_intermediate_joint" pos="0 0 0" axis="0 0 1" range="0 1.7" actuatorfrcrange="-1 1"/>
            <geom type="mesh" contype="0" conaffinity="0" group="1" density="0" rgba="0.7 0.7 0.7 1" mesh="link20_R"/>
            <geom type="mesh" rgba="0.7 0.7 0.7 1" mesh="link20_R"/>
            <site name="r_ring_site" pos="0 0.045 0" size="0.005" rgba="0 1 0 1" />
        </body>
    </body>
    <body name="R_pinky_proximal" pos="0.18971 -0.00028533 -0.025488" quat="-0.706138 0.0369975 -0.0369975 0.706138">
        <inertial pos="0.001297 0.011934 -0.0060001" quat="0.51013 0.489693 -0.510106 0.489653" mass="0.0042403" diaginertia="6.9397e-07 6.62865e-07 2.10915e-07"/>
        <joint name="R_pinky_proximal_joint" pos="0 0 0" axis="0 0 1" range="0 1.7" actuatorfrcrange="-1 1"/>
        <geom type="mesh" contype="0" conaffinity="0" group="1" density="0" rgba="0.7 0.7 0.7 1" mesh="link21_R"/>
        <geom type="mesh" rgba="0.7 0.7 0.7 1" mesh="link21_R"/>
        <body name="R_pinky_intermediate" pos="-0.0024229 0.032041 -0.001">
            <inertial pos="0.0024748 0.016203 -0.0050031" quat="0.47398 0.528862 -0.469291 0.524799" mass="0.0035996" diaginertia="4.4867e-07 4.43723e-07 6.56538e-08"/>
            <joint name="R_pinky_intermediate_joint" pos="0 0 0" axis="0 0 1" range="0 1.7" actuatorfrcrange="-1 1"/>
            <geom type="mesh" contype="0" conaffinity="0" group="1" density="0" rgba="0.7 0.7 0.7 1" mesh="link22_R"/>
            <geom type="mesh" rgba="0.7 0.7 0.7 1" mesh="link22_R"/>
            <site name="r_pinky_site" pos="0 0.04 0" size="0.005" rgba="0 1 0 1" />
        </body>
    </body>

  </worldbody>


  <actuator>
    <motor name="L_index_proximal_joint" joint="L_index_proximal_joint"/>
    <motor name="L_index_intermediate_joint" joint="L_index_intermediate_joint"/>
    <motor name="L_middle_proximal_joint" joint="L_middle_proximal_joint"/>
    <motor name="L_middle_intermediate_joint" joint="L_middle_intermediate_joint"/>
    <motor name="L_ring_proximal_joint" joint="L_ring_proximal_joint"/>
    <motor name="L_ring_intermediate_joint" joint="L_ring_intermediate_joint"/>
    <motor name="L_pinky_proximal_joint" joint="L_pinky_proximal_joint"/>
    <motor name="L_pinky_intermediate_joint" joint="L_pinky_intermediate_joint"/>
    <motor name="L_thumb_proximal_yaw_joint" joint="L_thumb_proximal_yaw_joint"/>
    <motor name="L_thumb_proximal_pitch_joint" joint="L_thumb_proximal_pitch_joint"/>
    <motor name="L_thumb_intermediate_joint" joint="L_thumb_intermediate_joint"/>
    <motor name="L_thumb_distal_joint" joint="L_thumb_distal_joint"/>
    <motor name="R_index_proximal_joint" joint="R_index_proximal_joint"/>
    <motor name="R_index_intermediate_joint" joint="R_index_intermediate_joint"/>
    <motor name="R_middle_proximal_joint" joint="R_middle_proximal_joint"/>
    <motor name="R_middle_intermediate_joint" joint="R_middle_intermediate_joint"/>
    <motor name="R_ring_proximal_joint" joint="R_ring_proximal_joint"/>
    <motor name="R_ring_intermediate_joint" joint="R_ring_intermediate_joint"/>
    <motor name="R_pinky_proximal_joint" joint="R_pinky_proximal_joint"/>
    <motor name="R_pinky_intermediate_joint" joint="R_pinky_intermediate_joint"/>
    <motor name="R_thumb_proximal_yaw_joint" joint="R_thumb_proximal_yaw_joint"/>
    <motor name="R_thumb_proximal_pitch_joint" joint="R_thumb_proximal_pitch_joint"/>
    <motor name="R_thumb_intermediate_joint" joint="R_thumb_intermediate_joint"/>
    <motor name="R_thumb_distal_joint" joint="R_thumb_distal_joint"/>
  </actuator>

</mujoco>