<mujoco model="dex3">
  <compiler angle="radian" meshdir="meshes"/>

  <asset>
    <mesh name="left_hand_palm_link" file="left_hand_palm_link.STL"/>
    <mesh name="left_hand_thumb_0_link" file="left_hand_thumb_0_link.STL"/>
    <mesh name="left_hand_thumb_1_link" file="left_hand_thumb_1_link.STL"/>
    <mesh name="left_hand_thumb_2_link" file="left_hand_thumb_2_link.STL"/>
    <mesh name="left_hand_middle_0_link" file="left_hand_middle_0_link.STL"/>
    <mesh name="left_hand_middle_1_link" file="left_hand_middle_1_link.STL"/>
    <mesh name="left_hand_index_0_link" file="left_hand_index_0_link.STL"/>
    <mesh name="left_hand_index_1_link" file="left_hand_index_1_link.STL"/>
    <mesh name="right_hand_palm_link" file="right_hand_palm_link.STL"/>
    <mesh name="right_hand_thumb_0_link" file="right_hand_thumb_0_link.STL"/>
    <mesh name="right_hand_thumb_1_link" file="right_hand_thumb_1_link.STL"/>
    <mesh name="right_hand_thumb_2_link" file="right_hand_thumb_2_link.STL"/>
    <mesh name="right_hand_middle_0_link" file="right_hand_middle_0_link.STL"/>
    <mesh name="right_hand_middle_1_link" file="right_hand_middle_1_link.STL"/>
    <mesh name="right_hand_index_0_link" file="right_hand_index_0_link.STL"/>
    <mesh name="right_hand_index_1_link" file="right_hand_index_1_link.STL"/>
  </asset>

  <worldbody>
      <body name="left_hand_thumb_0_link" pos="0.067 0.003 0">
        <inertial pos="-0.000884246 -0.00863407 0.000944293" quat="0.462991 0.643965 -0.460173 0.398986" mass="0.0862366" diaginertia="1.6546e-05 1.60058e-05 1.43741e-05"/>
        <joint name="left_hand_thumb_0_joint" pos="0 0 0" axis="0 1 0" range="-1.0472 1.0472" actuatorfrcrange="-2.45 2.45"/>
        <geom type="mesh" contype="0" conaffinity="0" group="1" density="0" rgba="0.7 0.7 0.7 1" mesh="left_hand_thumb_0_link"/>
        <geom type="mesh" rgba="0.7 0.7 0.7 1" mesh="left_hand_thumb_0_link"/>
        <body name="left_hand_thumb_1_link" pos="-0.0025 -0.0193 0">
          <inertial pos="-0.000827888 -0.0354744 -0.0003809" quat="0.685598 0.705471 -0.15207 0.0956069" mass="0.0588507" diaginertia="1.28514e-05 1.22902e-05 5.9666e-06"/>
          <joint name="left_hand_thumb_1_joint" pos="0 0 0" axis="0 0 1" range="-0.724312 1.0472" actuatorfrcrange="-1.4 1.4"/>
          <geom type="mesh" contype="0" conaffinity="0" group="1" density="0" rgba="0.7 0.7 0.7 1" mesh="left_hand_thumb_1_link"/>
          <geom size="0.01 0.015 0.01" pos="-0.001 -0.032 0" type="box" rgba="0.7 0.7 0.7 1"/>
          <body name="left_hand_thumb_2_link" pos="0 -0.0458 0">
            <inertial pos="-0.00171735 -0.0262819 0.000107789" quat="0.703174 0.710977 -0.00017564 -0.00766553" mass="0.0203063" diaginertia="4.61314e-06 3.86645e-06 1.53495e-06"/>
            <joint name="left_hand_thumb_2_joint" pos="0 0 0" axis="0 0 1" range="0 1.74533" actuatorfrcrange="-1.4 1.4"/>
            <geom type="mesh" contype="0" conaffinity="0" group="1" density="0" rgba="0.7 0.7 0.7 1" mesh="left_hand_thumb_2_link"/>
            <geom type="mesh" rgba="0.7 0.7 0.7 1" mesh="left_hand_thumb_2_link"/>
            <site name="l_thumb_site" pos="0 -0.05 0" size="0.005" rgba="1 0 0 1" />
          </body>
        </body>
      
      </body>
      <body name="left_hand_middle_0_link" pos="0.1192 0.0046 -0.0285">
        <inertial pos="0.0354744 0.000827888 0.0003809" quat="0.391313 0.552395 0.417187 0.606373" mass="0.0588507" diaginertia="1.28514e-05 1.22902e-05 5.9666e-06"/>
        <joint name="left_hand_middle_0_joint" pos="0 0 0" axis="0 0 1" range="-1.5708 0" actuatorfrcrange="-1.4 1.4"/>
        <geom type="mesh" contype="0" conaffinity="0" group="1" density="0" rgba="0.7 0.7 0.7 1" mesh="left_hand_middle_0_link"/>
        <geom type="mesh" rgba="0.7 0.7 0.7 1" mesh="left_hand_middle_0_link"/>
        <body name="left_hand_middle_1_link" pos="0.0458 0 0">
          <inertial pos="0.0262819 0.00171735 -0.000107789" quat="0.502612 0.491799 0.502639 0.502861" mass="0.0203063" diaginertia="4.61314e-06 3.86645e-06 1.53495e-06"/>
          <joint name="left_hand_middle_1_joint" pos="0 0 0" axis="0 0 1" range="-1.74533 0" actuatorfrcrange="-1.4 1.4"/>
          <geom type="mesh" contype="0" conaffinity="0" group="1" density="0" rgba="0.7 0.7 0.7 1" mesh="left_hand_middle_1_link"/>
          <geom type="mesh" rgba="0.7 0.7 0.7 1" mesh="left_hand_middle_1_link"/>
          <site name="l_middle_site" pos="0.05 0 0" size="0.005" rgba="1 0 0 1" />
        </body>
      </body>
      <body name="left_hand_index_0_link" pos="0.1192 0.0046 0.0285">
        <inertial pos="0.0354744 0.000827888 0.0003809" quat="0.391313 0.552395 0.417187 0.606373" mass="0.0588507" diaginertia="1.28514e-05 1.22902e-05 5.9666e-06"/>
        <joint name="left_hand_index_0_joint" pos="0 0 0" axis="0 0 1" range="-1.5708 0" actuatorfrcrange="-1.4 1.4"/>
        <geom type="mesh" contype="0" conaffinity="0" group="1" density="0" rgba="0.7 0.7 0.7 1" mesh="left_hand_index_0_link"/>
        <geom type="mesh" rgba="0.7 0.7 0.7 1" mesh="left_hand_index_0_link"/>
        <body name="left_hand_index_1_link" pos="0.0458 0 0">
          <inertial pos="0.0262819 0.00171735 -0.000107789" quat="0.502612 0.491799 0.502639 0.502861" mass="0.0203063" diaginertia="4.61314e-06 3.86645e-06 1.53495e-06"/>
          <joint name="left_hand_index_1_joint" pos="0 0 0" axis="0 0 1" range="-1.74533 0" actuatorfrcrange="-1.4 1.4"/>
          <geom type="mesh" contype="0" conaffinity="0" group="1" density="0" rgba="0.7 0.7 0.7 1" mesh="left_hand_index_1_link"/>
          <geom type="mesh" rgba="0.7 0.7 0.7 1" mesh="left_hand_index_1_link"/>
          <site name="l_index_site" pos="0.05 0 0" size="0.005" rgba="1 0 0 1" />
        </body>
      </body>


      <body name="right_hand_thumb_0_link" pos="0.067 -0.003 0">
        <inertial pos="-0.000884246 0.00863407 0.000944293" quat="0.643965 0.462991 -0.398986 0.460173" mass="0.0862366" diaginertia="1.6546e-05 1.60058e-05 1.43741e-05"/>
        <joint name="right_hand_thumb_0_joint" pos="0 0 0" axis="0 1 0" range="-1.0472 1.0472" actuatorfrcrange="-2.45 2.45"/>
        <geom type="mesh" contype="0" conaffinity="0" group="1" density="0" rgba="0.7 0.7 0.7 1" mesh="right_hand_thumb_0_link"/>
        <geom type="mesh" rgba="0.7 0.7 0.7 1" mesh="right_hand_thumb_0_link"/>
        <body name="right_hand_thumb_1_link" pos="-0.0025 0.0193 0">
          <inertial pos="-0.000827888 0.0354744 -0.0003809" quat="0.705471 0.685598 -0.0956069 0.15207" mass="0.0588507" diaginertia="1.28514e-05 1.22902e-05 5.9666e-06"/>
          <joint name="right_hand_thumb_1_joint" pos="0 0 0" axis="0 0 1" range="-1.0472 0.724312" actuatorfrcrange="-1.4 1.4"/>
          <geom type="mesh" contype="0" conaffinity="0" group="1" density="0" rgba="0.7 0.7 0.7 1" mesh="right_hand_thumb_1_link"/>
          <geom size="0.01 0.015 0.01" pos="-0.001 0.032 0" type="box" rgba="0.7 0.7 0.7 1"/>
          <body name="right_hand_thumb_2_link" pos="0 0.0458 0">
            <inertial pos="-0.00171735 0.0262819 0.000107789" quat="0.710977 0.703174 0.00766553 0.00017564" mass="0.0203063" diaginertia="4.61314e-06 3.86645e-06 1.53495e-06"/>
            <joint name="right_hand_thumb_2_joint" pos="0 0 0" axis="0 0 1" range="-1.74533 0" actuatorfrcrange="-1.4 1.4"/>
            <geom type="mesh" contype="0" conaffinity="0" group="1" density="0" rgba="0.7 0.7 0.7 1" mesh="right_hand_thumb_2_link"/>
            <geom type="mesh" rgba="0.7 0.7 0.7 1" mesh="right_hand_thumb_2_link"/>
            <site name="r_thumb_site" pos="0 0.05 0" size="0.005" rgba="1 0 0 1" />
          </body>
        </body>
      </body>
      <body name="right_hand_middle_0_link" pos="0.1192 -0.0046 -0.0285">
        <inertial pos="0.0354744 -0.000827888 0.0003809" quat="0.606373 0.417187 0.552395 0.391313" mass="0.0588507" diaginertia="1.28514e-05 1.22902e-05 5.9666e-06"/>
        <joint name="right_hand_middle_0_joint" pos="0 0 0" axis="0 0 1" range="0 1.5708" actuatorfrcrange="-1.4 1.4"/>
        <geom type="mesh" contype="0" conaffinity="0" group="1" density="0" rgba="0.7 0.7 0.7 1" mesh="right_hand_middle_0_link"/>
        <geom type="mesh" rgba="0.7 0.7 0.7 1" mesh="right_hand_middle_0_link"/>
        <body name="right_hand_middle_1_link" pos="0.0458 0 0">
          <inertial pos="0.0262819 -0.00171735 -0.000107789" quat="0.502861 0.502639 0.491799 0.502612" mass="0.0203063" diaginertia="4.61314e-06 3.86645e-06 1.53495e-06"/>
          <joint name="right_hand_middle_1_joint" pos="0 0 0" axis="0 0 1" range="0 1.74533" actuatorfrcrange="-1.4 1.4"/>
          <geom type="mesh" contype="0" conaffinity="0" group="1" density="0" rgba="0.7 0.7 0.7 1" mesh="right_hand_middle_1_link"/>
          <geom type="mesh" rgba="0.7 0.7 0.7 1" mesh="right_hand_middle_1_link"/>
          <site name="r_middle_site" pos="0.05 0 0" size="0.005" rgba="1 0 0 1" />
        </body>
      </body>
      <body name="right_hand_index_0_link" pos="0.1192 -0.0046 0.0285">
        <inertial pos="0.0354744 -0.000827888 0.0003809" quat="0.606373 0.417187 0.552395 0.391313" mass="0.0588507" diaginertia="1.28514e-05 1.22902e-05 5.9666e-06"/>
        <joint name="right_hand_index_0_joint" pos="0 0 0" axis="0 0 1" range="0 1.5708" actuatorfrcrange="-1.4 1.4"/>
        <geom type="mesh" contype="0" conaffinity="0" group="1" density="0" rgba="0.7 0.7 0.7 1" mesh="right_hand_index_0_link"/>
        <geom type="mesh" rgba="0.7 0.7 0.7 1" mesh="right_hand_index_0_link"/>
        <body name="right_hand_index_1_link" pos="0.0458 0 0">
          <inertial pos="0.0262819 -0.00171735 -0.000107789" quat="0.502861 0.502639 0.491799 0.502612" mass="0.0203063" diaginertia="4.61314e-06 3.86645e-06 1.53495e-06"/>
          <joint name="right_hand_index_1_joint" pos="0 0 0" axis="0 0 1" range="0 1.74533" actuatorfrcrange="-1.4 1.4"/>
          <geom type="mesh" contype="0" conaffinity="0" group="1" density="0" rgba="0.7 0.7 0.7 1" mesh="right_hand_index_1_link"/>
          <geom type="mesh" rgba="0.7 0.7 0.7 1" mesh="right_hand_index_1_link"/>
          <site name="r_index_site" pos="0.05 0 0" size="0.005" rgba="1 0 0 1" />
        </body>
      </body>

  </worldbody>

  <actuator>
    <motor name="left_hand_thumb_0_joint" joint="left_hand_thumb_0_joint"/>
    <motor name="left_hand_thumb_1_joint" joint="left_hand_thumb_1_joint"/>
    <motor name="left_hand_thumb_2_joint" joint="left_hand_thumb_2_joint"/>
    <motor name="left_hand_middle_0_joint" joint="left_hand_middle_0_joint"/>
    <motor name="left_hand_middle_1_joint" joint="left_hand_middle_1_joint"/>
    <motor name="left_hand_index_0_joint" joint="left_hand_index_0_joint"/>
    <motor name="left_hand_index_1_joint" joint="left_hand_index_1_joint"/>
    <motor name="right_hand_thumb_0_joint" joint="right_hand_thumb_0_joint"/>
    <motor name="right_hand_thumb_1_joint" joint="right_hand_thumb_1_joint"/>
    <motor name="right_hand_thumb_2_joint" joint="right_hand_thumb_2_joint"/>
    <motor name="right_hand_index_0_joint" joint="right_hand_index_0_joint"/>
    <motor name="right_hand_index_1_joint" joint="right_hand_index_1_joint"/>
    <motor name="right_hand_middle_0_joint" joint="right_hand_middle_0_joint"/>
    <motor name="right_hand_middle_1_joint" joint="right_hand_middle_1_joint"/>
  </actuator>

  <!-- setup scene -->
  <statistic center="1.0 0.7 1.0" extent="0.8"/>
  <visual>
    <headlight diffuse="0.6 0.6 0.6" ambient="0.1 0.1 0.1" specular="0.9 0.9 0.9"/>
    <rgba haze="0.15 0.25 0.35 1"/>
    <global azimuth="-140" elevation="-20"/>
  </visual>
  <asset>
    <texture type="skybox" builtin="flat" rgb1="0 0 0" rgb2="0 0 0" width="512" height="3072"/>
    <texture type="2d" name="groundplane" builtin="checker" mark="edge" rgb1="0.2 0.3 0.4" rgb2="0.1 0.2 0.3" markrgb="0.8 0.8 0.8" width="300" height="300"/>
    <material name="groundplane" texture="groundplane" texuniform="true" texrepeat="5 5" reflectance="0.2"/>
  </asset>
  <worldbody>
    <light pos="1 0 3.5" dir="0 0 -1" directional="true"/>
    <geom name="floor" size="0 0 0.05" type="plane" material="groundplane"/>
  </worldbody>
</mujoco>